# Nicolas Ternisien <nicolas@bureau-cornavin.com>, 2016.
# Eric Bischoff <eric@bureau-cornavin.com>, 2016.
msgid ""
msgstr ""
"Project-Id-Version: univention-management-console-module-diagnostic\n"
"Report-Msgid-Bugs-To: packages@univention.de\n"
"POT-Creation-Date: 2017-04-14 00:29+0200\n"
"PO-Revision-Date: 2016-07-10 14:04+0100\n"
"Last-Translator: Eric Bischoff <eric@bureau-cornavin.com>\n"
"Language-Team: French <fr@bureau-cornavin.com>\n"
"Language: fr\n"
"MIME-Version: 1.0\n"
"Content-Type: text/plain; charset=UTF-8\n"
"Content-Transfer-Encoding: 8bit\n"
"Plural-Forms: nplurals=2; plural=(n > 1);\n"
"X-Generator: Lokalize 2.0\n"

#: umc/python/diagnostic/plugins/nameserver.py:15
#, python-format
msgid "%d of the configured nameservers are not responding to DNS queries."
msgstr "%d des serveurs de noms configurés ne répondent pas aux requêtes DNS."

#: umc/python/diagnostic/plugins/nameserver.py:46
msgid "A timeout occurred while reaching the nameserver (is it online?)."
msgstr "Délai dépassé lors de l'accès au serveur de noms (est-il connecté ?)."

#: umc/python/diagnostic/plugins/security_limits.py:31
msgid "Adjust to suggested limits"
msgstr "Ajuster aux limites suggérées"

#: umc/python/diagnostic/plugins/gateway.py:11
msgid "Gateway is not reachable"
msgstr "La passerelle n'est pas accessible"

#: umc/python/diagnostic/plugins/ssh_connection.py:54
msgid "Host key for server does not match"
msgstr "La clé d'hôte pour ce serveur ne correspond pas"

#: umc/python/diagnostic/plugins/nameserver.py:17
msgid ""
"If the problem persists make sure the nameserver is connected to the network "
"and the forwarders are able to reach the internet (www.univention.de)."
msgstr ""
"Si le problème persiste, veuillez vous assurer que le serveur de noms est "
"connecté au réseau et que les transmetteurs (forwarders) peuvent accéder à "
"Internet (www.univention.de)."

#: umc/python/diagnostic/plugins/gateway.py:14
msgid "If these settings are correct the problem relies in the gateway itself:"
msgstr ""
"Si ces réglages sont corrects, le problème provient de la passerelle elle-"
"même :"

#: umc/python/diagnostic/plugins/security_limits.py:19
#, python-brace-format
msgid ""
"It is suggested to increase the security limits either manually by using "
"{ucr} or to automatically adjust them to the suggested limits:"
msgstr ""
"Il est conseillé d'augmenter les limites de sécurité manuellement en "
"utilisant {ucr} ou de les ajuster automatiquement aux limites proposées :"

#: umc/python/diagnostic/plugins/ssh_connection.py:59
#, python-format
msgid ""
"Login to the remote server with the uid %(uid)s and the password from /etc/"
"machine.secret failed. "
msgstr ""
"Échec de la connexion au serveur distant avec l'UID %(uid)s et le mot de "
"passe issu de « /etc/machine.secret ». "

#: umc/python/diagnostic/plugins/package_status.py:14
msgid ""
"Login to the system as root via ssh and run the command \"dpkg --configure -a"
"\" in order to correct the packages status."
msgstr ""
"Connectez-vous au système en tant que super utilisateur par le biais de SSH "
"et exécutez la commande « dpkg --configure -a » afin de corriger l'état des "
"paquetages."

#: umc/python/diagnostic/plugins/ssh_connection.py:58
msgid "Machine authentication failed"
msgstr "Échec de l'authentification à la machine"

#: umc/python/diagnostic/plugins/gateway.py:15
msgid "Make sure the hardware of the gateway device is working properly."
msgstr ""
"Veuillez vous assurer que l'équipement de passerelle fonctionne "
"convenablement."

#: umc/python/diagnostic/plugins/package_status.py:15
msgid ""
"More information about the cause can be gained by executing \"dpkg --audit\"."
msgstr ""
"Des informations complémentaires sur l'origine du problème peuvent être "
"obtenues en exécutant « dpkg --audit »."

#: umc/python/diagnostic/plugins/nameserver.py:13
msgid "Nameserver(s) are not responsive"
msgstr "Le ou les serveurs de noms ne sont pas réactifs"

#: umc/python/diagnostic/plugins/package_status.py:11
msgid "Package status corrupt"
msgstr "Corruption de l'état du paquetage"

#: umc/python/diagnostic/plugins/ssh_connection.py:60
msgid ""
"Please check /var/log/auth.log on the remote server for further information."
msgstr ""
"Veuillez vérifier « /var/log/auth.log » sur le serveur distant pour plus "
"d'informations."

#: umc/python/diagnostic/plugins/nameserver.py:16
msgid ""
"Please make sure the DNS settings in the {setup:network} are correctly set "
"up."
msgstr ""
"Veuillez vous assurer que les réglages DNS dans {setup:network} sont "
"correctement définis."

#: umc/python/diagnostic/plugins/ssh_connection.py:56
#, python-format
msgid ""
"Please repair the host key of the remote server in /root/.ssh/known_hosts on "
"%(fqdn)s."
msgstr ""
"Veuillez réparer la clé d'hôte du serveur distant dans « /root/.ssh/"
"known_hosts » pour %(fqdn)s."

#: umc/python/diagnostic/plugins/proxy.py:15
msgid "Proxy server failure"
msgstr "Échec du serveur mandataire"

#: umc/python/diagnostic/plugins/ssh_connection.py:16
msgid "SSH connection to UCS server failed!"
msgstr "Échec de la connexion SSH au serveur UCS !"

#: umc/python/diagnostic/plugins/security_limits.py:14
msgid "Security limits exceeded"
msgstr "Limites de sécurité atteintes"

#: umc/python/diagnostic/__init__.py:279
msgid "Test again"
msgstr "Tester à nouveau"

#: umc/python/diagnostic/plugins/ssh_connection.py:52
msgid ""
"The following list shows the affected remote servers and the reason for the "
"failed ssh connection:"
msgstr ""
"La liste suivante affiche les serveurs distants affectés et la raison de "
"l'échec de la connexion SSH :"

#: umc/python/diagnostic/plugins/gateway.py:13
#, python-format
msgid ""
"The gateway %r could not be reached. Please make sure the gateway and "
"related network settings are correctly configured by using the {setup:"
"network}."
msgstr ""
"Impossible d'atteindre la passerelle %r. Veuillez vous assurer que la "
"passerelle et les réglages réseaux associés soient configurés correctement "
"en utilisant {setup:network}."

#: umc/python/diagnostic/plugins/proxy.py:67
msgid ""
"The hostname of the proxy could not be resolved. May check your DNS "
"configuration."
msgstr ""
"Impossible de résoudre le nom d'hôte du serveur mandataire. Veuillez "
"vérifier votre configuration DNS."

#: umc/python/diagnostic/plugins/security_limits.py:61
msgid "The limits have been adjusted to the suggested value."
msgstr "Les limites ont été adaptées à la valeur suggérée."

#: umc/python/diagnostic/plugins/nameserver.py:43
#, python-format
msgid "The nameserver %(nameserver)s (UCR variable %(var)r) is not responsive:"
msgstr ""
"Le serveur de noms %(nameserver)s (variable UCR %(var)r) n'est pas réactif :"

#: umc/python/diagnostic/plugins/package_status.py:13
#, python-format
msgid "The package status of %s packages is corrupt."
msgstr "Les états des paquetages %s sont corrompus."

#: umc/python/diagnostic/plugins/proxy.py:65
#, python-format
msgid ""
"The proxy host could not be reached. Make sure that hostname (%(hostname)r) "
"and port (%(port)r) are correctly set up."
msgstr ""
"Impossible d'atteindre le serveur mandataire. Veuillez vous assurer que le "
"nom d'hôte (%(hostname)r) et le port (%(port)r) sont correctement définis."

#: umc/python/diagnostic/plugins/proxy.py:82
#, python-format
msgid ""
"The proxy server is reachable but the HTTP response status code (%d) does "
"not indicate success."
msgstr ""
"Le serveur mandataire est accessible, mais le code d'état de la réponse HTTP "
"(%d) n'indique pas une réussite."

#: umc/python/diagnostic/plugins/security_limits.py:17
msgid ""
"The security limits (e.g. for max_open_files) are currently not configured "
"properly."
msgstr ""
"Les limites de sécurité (par ex. pour « max_open_files ») ne sont pas pas "
"configurées correctement."

#: umc/python/diagnostic/plugins/proxy.py:69
#, python-format
msgid ""
"The server did not respond within %d seconds. Please check your network "
"configuration."
msgstr ""
"Le serveur n'a pas répondu dans les %d secondes. Veuillez vérifier votre "
"configuration réseau."

#: umc/python/diagnostic/plugins/ssh_connection.py:51
msgid "The ssh connection to at least one other UCS server failed. "
msgstr "Échec de la connexion SSH à au moins un autre serveur UCS."

#: umc/python/diagnostic/plugins/ssh_connection.py:55
msgid ""
"The ssh host key of the remote server has changed (maybe the host was "
"reinstalled). "
msgstr ""
"La clé d'hôte SSH du serveur distant a été modifiée (l'hôte a peut-être été "
"réinstallé)."

#: umc/python/diagnostic/plugins/proxy.py:16
msgid ""
"There was an error using the proxy server. The {setup:network} can be used "
"to change the proxy configuration.\n"
msgstr ""
"Erreur lors de l'utilisation du serveur mandataire. {setup:network} peut "
"être utilisé pour modifier la configuration du serveur mandataire.\n"

#: umc/python/diagnostic/plugins/security_limits.py:18
msgid ""
"This can cause several different serious problems (e.g. the login at samba "
"servers may be impossible, file operations (copy, move) on shares can fail, "
"etc.)"
msgstr ""
"Cela peut causer un certain nombre de problèmes importants (ex. : la "
"connexion aux serveurs Samba peut être impossible, les opérations sur les "
"fichiers (copie, déplacement) sur les partages peuvent échouer, etc.)"

#: umc/python/diagnostic/plugins/proxy.py:83
#, python-format
msgid ""
"This warning might be harmless. Nevertheless make sure the authentication "
"credentials (if any) are correct and the proxy server ACLs do not forbid "
"requests to %s."
msgstr ""
"Cet avertissement est peut-être sans danger. Veuillez cependant vous assurer "
"que les preuves d'identité (s'il y en a) sont correctes et que les ACL du "
"serveur mandataire n'interdisent pas les requêtes vers %s."

#: umc/python/diagnostic/plugins/package_status.py:28
msgid "some"
msgstr "certains"
